Traceback (most recent call last):
  File "/opt/luftsachsen/venv/lib/python3.4/site-packages/requests/packages/urllib3/connectionpool.py", line 595, in urlopen
    chunked=chunked)
  File "/opt/luftsachsen/venv/lib/python3.4/site-packages/requests/packages/urllib3/connectionpool.py", line 393, in _make_request
    six.raise_from(e, None)
  File "<string>", line 2, in raise_from
  File "/opt/luftsachsen/venv/lib/python3.4/site-packages/requests/packages/urllib3/connectionpool.py", line 389, in _make_request
    httplib_response = conn.getresponse()
  File "/usr/lib/python3.4/http/client.py", line 1209, in getresponse
    response.begin()
  File "/usr/lib/python3.4/http/client.py", line 380, in begin
    version, status, reason = self._read_status()
  File "/usr/lib/python3.4/http/client.py", line 350, in _read_status
    raise BadStatusLine(line)
http.client.BadStatusLine: ''

During handling of the above exception, another exception occurred:

Traceback (most recent call last):
  File "/opt/luftsachsen/venv/lib/python3.4/site-packages/requests/adapters.py", line 423, in send
    timeout=timeout
  File "/opt/luftsachsen/venv/lib/python3.4/site-packages/requests/packages/urllib3/connectionpool.py", line 640, in urlopen
    _stacktrace=sys.exc_info()[2])
  File "/opt/luftsachsen/venv/lib/python3.4/site-packages/requests/packages/urllib3/util/retry.py", line 261, in increment
    raise six.reraise(type(error), error, _stacktrace)
  File "/opt/luftsachsen/venv/lib/python3.4/site-packages/requests/packages/urllib3/packages/six.py", line 685, in reraise
    raise value.with_traceback(tb)
  File "/opt/luftsachsen/venv/lib/python3.4/site-packages/requests/packages/urllib3/connectionpool.py", line 595, in urlopen
    chunked=chunked)
  File "/opt/luftsachsen/venv/lib/python3.4/site-packages/requests/packages/urllib3/connectionpool.py", line 393, in _make_request
    six.raise_from(e, None)
  File "<string>", line 2, in raise_from
  File "/opt/luftsachsen/venv/lib/python3.4/site-packages/requests/packages/urllib3/connectionpool.py", line 389, in _make_request
    httplib_response = conn.getresponse()
  File "/usr/lib/python3.4/http/client.py", line 1209, in getresponse
    response.begin()
  File "/usr/lib/python3.4/http/client.py", line 380, in begin
    version, status, reason = self._read_status()
  File "/usr/lib/python3.4/http/client.py", line 350, in _read_status
    raise BadStatusLine(line)
requests.packages.urllib3.exceptions.ProtocolError: ('Connection aborted.', BadStatusLine("''",))

During handling of the above exception, another exception occurred:

Traceback (most recent call last):
  File "/opt/luftsachsen/Luftqualitaet-src/AirImport/importer.py", line 148, in get_csv_data
    'n. def.', '').replace(',', '.').replace(
  File "/opt/luftsachsen/Luftqualitaet-src/AirImport/importer.py", line 160, in _get_string
    response = self._session.post(uws.URL, self._post_data, timeout = 45)
  File "/opt/luftsachsen/venv/lib/python3.4/site-packages/requests/sessions.py", line 522, in post
    return self.request('POST', url, data=data, json=json, **kwargs)
  File "/opt/luftsachsen/venv/lib/python3.4/site-packages/requests/sessions.py", line 475, in request
    resp = self.send(prep, **send_kwargs)
  File "/opt/luftsachsen/venv/lib/python3.4/site-packages/requests/sessions.py", line 596, in send
    r = adapter.send(request, **kwargs)
  File "/opt/luftsachsen/venv/lib/python3.4/site-packages/requests/adapters.py", line 473, in send
    raise ConnectionError(err, request=request)
requests.exceptions.ConnectionError: ('Connection aborted.', BadStatusLine("''",))
